Workbook

Sheet 인덱스
A1: 지반침하 스마트관리 시스템 작업목록
A3: 버전 | B3: V0.2 (전체본, DevOps 실제 날짜)
A4: 기준일 | B4: 46315
A5: 기간 | B5: 2026-08-03 부터 2026-10-20 까지 한 일 + 그 뒤 할 일
A6: 작성 | B6: (주)이노팸
A7: 담당자 | B7: FE 김재헌·정하늘 / BE 김규영·조혜인·전재환·유소운·최성민 / DevOps 박가람
A8: 날짜 성격 | B8: FE: 사람별로, BE: 팀 한 줄기로 8/3 부터 순서대로 배치한 계획형 일정(BE 5명은 영역별로 나눠 맡음). DevOps: dev0 저장소 docs/history 의 실제 날짜(10/06 시작, 하루에 여러 작업) — 예정만 기준일 뒤로 배정
A9: 요구사항ID 출처 | B9: 지반침하스마트관리시스템_요구사항정의서-V1.0.xlsx 의 세부요구사항ID(SFR·NFR)
A10: 화면ID 출처 | B10: 지반침하 스마트관리 시스템_화면정의서-V1.0.pptx 의 화면 ID(SCR-001–013, 아래 표)
A12: 시트
A13: 시트 | B13: 내용 | C13: 담당자 | D13: 작업 수 | E13: 완료 | F13: 진행 | G13: 예정 | H13: 공수 합(일)
A14: FE | B14: 프런트엔드 — 지도·레이어·조회·관리자 화면·내보내기·품질 검사 | C14: 김재헌, 정하늘 | D14: =COUNTA(FE!$A:$A)-1 | E14: =COUNTIF(FE!$I:$I,"완료") | F14: =COUNTIF(FE!$I:$I,"진행") | G14: =COUNTIF(FE!$I:$I,"예정") | H14: =SUM(FE!$H:$H)
A15: BE | B15: 백엔드 — 자료 파이프라인·격자·지수(CSI)·API·객체 저장소·품질 검사 | C15: 김규영, 조혜인, 전재환, 유소운, 최성민 | D15: =COUNTA(BE!$A:$A)-1 | E15: =COUNTIF(BE!$I:$I,"완료") | F15: =COUNTIF(BE!$I:$I,"진행") | G15: =COUNTIF(BE!$I:$I,"예정") | H15: =SUM(BE!$H:$H)
A16: DevOps | B16: 운영(dev0, 실제 날짜) — Proxmox·Talos·Cilium·스토리지·백업·CI 러너·GitOps 배포 | C16: 박가람 | D16: =COUNTA(DevOps!$A:$A)-1 | E16: =COUNTIF(DevOps!$I:$I,"완료") | F16: =COUNTIF(DevOps!$I:$I,"진행") | G16: =COUNTIF(DevOps!$I:$I,"예정") | H16: =SUM(DevOps!$H:$H)
A17: 합계 | D17: =SUM(D14:D16) | E17: =SUM(E14:E16) | F17: =SUM(F14:F16) | G17: =SUM(G14:G16) | H17: =SUM(H14:H16)
A19: 담당자
A20: 담당자 | B20: 시트 | C20: 작업 수 | D20: 완료 | E20: 진행 | F20: 예정 | G20: 공수 합(일)
A21: 김재헌 | B21: FE | C21: =COUNTIF(FE!$E:$E,"김재헌") | D21: =COUNTIFS(FE!$E:$E,"김재헌",FE!$I:$I,"완료") | E21: =COUNTIFS(FE!$E:$E,"김재헌",FE!$I:$I,"진행") | F21: =COUNTIFS(FE!$E:$E,"김재헌",FE!$I:$I,"예정") | G21: =SUMIF(FE!$E:$E,"김재헌",FE!$H:$H)
A22: 정하늘 | B22: FE | C22: =COUNTIF(FE!$E:$E,"정하늘") | D22: =COUNTIFS(FE!$E:$E,"정하늘",FE!$I:$I,"완료") | E22: =COUNTIFS(FE!$E:$E,"정하늘",FE!$I:$I,"진행") | F22: =COUNTIFS(FE!$E:$E,"정하늘",FE!$I:$I,"예정") | G22: =SUMIF(FE!$E:$E,"정하늘",FE!$H:$H)
A23: 김규영 | B23: BE | C23: =COUNTIF(BE!$E:$E,"김규영") | D23: =COUNTIFS(BE!$E:$E,"김규영",BE!$I:$I,"완료") | E23: =COUNTIFS(BE!$E:$E,"김규영",BE!$I:$I,"진행") | F23: =COUNTIFS(BE!$E:$E,"김규영",BE!$I:$I,"예정") | G23: =SUMIF(BE!$E:$E,"김규영",BE!$H:$H)
A24: 조혜인 | B24: BE | C24: =COUNTIF(BE!$E:$E,"조혜인") | D24: =COUNTIFS(BE!$E:$E,"조혜인",BE!$I:$I,"완료") | E24: =COUNTIFS(BE!$E:$E,"조혜인",BE!$I:$I,"진행") | F24: =COUNTIFS(BE!$E:$E,"조혜인",BE!$I:$I,"예정") | G24: =SUMIF(BE!$E:$E,"조혜인",BE!$H:$H)
A25: 전재환 | B25: BE | C25: =COUNTIF(BE!$E:$E,"전재환") | D25: =COUNTIFS(BE!$E:$E,"전재환",BE!$I:$I,"완료") | E25: =COUNTIFS(BE!$E:$E,"전재환",BE!$I:$I,"진행") | F25: =COUNTIFS(BE!$E:$E,"전재환",BE!$I:$I,"예정") | G25: =SUMIF(BE!$E:$E,"전재환",BE!$H:$H)
A26: 유소운 | B26: BE | C26: =COUNTIF(BE!$E:$E,"유소운") | D26: =COUNTIFS(BE!$E:$E,"유소운",BE!$I:$I,"완료") | E26: =COUNTIFS(BE!$E:$E,"유소운",BE!$I:$I,"진행") | F26: =COUNTIFS(BE!$E:$E,"유소운",BE!$I:$I,"예정") | G26: =SUMIF(BE!$E:$E,"유소운",BE!$H:$H)
A27: 최성민 | B27: BE | C27: =COUNTIF(BE!$E:$E,"최성민") | D27: =COUNTIFS(BE!$E:$E,"최성민",BE!$I:$I,"완료") | E27: =COUNTIFS(BE!$E:$E,"최성민",BE!$I:$I,"진행") | F27: =COUNTIFS(BE!$E:$E,"최성민",BE!$I:$I,"예정") | G27: =SUMIF(BE!$E:$E,"최성민",BE!$H:$H)
A28: 박가람 | B28: DevOps | C28: =COUNTIF(DevOps!$E:$E,"박가람") | D28: =COUNTIFS(DevOps!$E:$E,"박가람",DevOps!$I:$I,"완료") | E28: =COUNTIFS(DevOps!$E:$E,"박가람",DevOps!$I:$I,"진행") | F28: =COUNTIFS(DevOps!$E:$E,"박가람",DevOps!$I:$I,"예정") | G28: =SUMIF(DevOps!$E:$E,"박가람",DevOps!$H:$H)
A30: 작성 규칙
A31: ID | B31: 시트 이름 + 번호(FE-001, BE-001, DEVOPS-001). 시작일 순. 번호는 바뀌지 않는 식별자로 쓴다.
A32: 상태 | B32: 완료: 기준일 이전에 끝남 / 진행: 기준일에 하고 있음(종료일은 예정일) / 예정: 기준일 뒤 시작
A33: 날짜 | B33: 주말과 아래 공휴일을 뺀 근무일만 쓴다. FE·BE 는 같은 담당자의 작업 기간이 겹치지 않는다. DevOps 는 실제 날짜라 하루에 여러 작업이 있고, 공수 합은 사람·일이 아니다. 공수(일)는 NETWORKDAYS 로 계산하되 휴일에 한 실제 작업(DevOps 10/09 한글날·10/10 토요일)은 최소 1일로 센다.
A34: 영역 | B34: 시트 안에서 작업을 묶는 작은 분류(FE: 지도·패널·조회·관리자·품질… / BE: 자료·격자·지수·API·저장소·DB·타일… / DevOps: 가상화·클러스터·네트워크·스토리지·백업·CI·GitOps…)
A35: 관련 요구사항ID | B35: 요구사항정의서의 세부요구사항ID. 기능은 SFR-00n-0m, 비기능은 NFR-00n-0m. 직접 대응이 없으면 '-'
A36: 관련 화면ID | B36: 화면정의서의 SCR-001–013. 화면이 없는 작업은 '-'
A37: 산출물 | B37: 저장소 경로, 파일, GitHub 이슈 번호, 운영 저장소 할 일 번호(W##)
A39: 공휴일(근무일 계산에서 제외)
A40: 이름 | B40: 날짜
A41: 광복절 대체공휴일 | B41: 46251
A42: 추석 연휴 | B42: 46289
A43: 추석 | B43: 46290
A44: 추석 대체공휴일 | B44: 46293
A45: 개천절 대체공휴일 | B45: 46300
...

Sheet FE
A1: ID | B1: 영역 | C1: 작업명 | D1: 작업 내용 | E1: 담당자 | F1: 시작일 | G1: 종료일 | H1: 공수(일) | I1: 상태 | J1: 관련 요구사항ID | K1: 관련 화면ID | L1: 산출물 | M1: 비고
A2: FE-001 | B2: 골격 | C2: FE 프로젝트 골격 | D2: Vite + React 프로젝트 생성, 폴더 구조(components·lib·styles·data), 개발 서버·빌드 스크립트, .env 로 브이월드 키 분리 | E2: 김재헌 | F2: 46237 | G2: 46239 | H2: =MAX(1,NETWORKDAYS(F2,G2,인덱스!$B$41:$B$47)) | I2: 완료 | J2: NFR-009-01 | K2: - | L2: app/, vite.config, .env.example
A3: FE-002 | B3: 디자인 | C3: 디자인 토큰·아이콘·글꼴 | D3: GEO-AI 변수(Primary·Neutral·etc·Body·Btn)를 tokens.css 로 옮기기, 아이콘 SVG 정리(Figma 찌꺼기 제거), Roboto·Noto Sans KR·자간 −0.02em | E3: 정하늘 | F3: 46237 | G3: 46238 | H3: =MAX(1,NETWORKDAYS(F3,G3,인덱스!$B$41:$B$47)) | I3: 완료 | J3: NFR-009-01 | K3: - | L3: src/styles/tokens.css, public/icons/
A4: FE-003 | B4: 화면 | C4: 헤더·GNB | D4: 알림 배지(직전 분석 대비 신규·상향 건수), 도움말, 관리자, 홈 — 실제로 동작하는 것만 연결 | E4: 정하늘 | F4: 46239 | G4: 46240 | H4: =MAX(1,NETWORKDAYS(F4,G4,인덱스!$B$41:$B$47)) | I4: 완료 | J4: NFR-009-01 | K4: SCR-001 | L4: components/Header
A5: FE-004 | B5: 지도 | C5: 지도 뷰어 기반(MapPane) | D5: Leaflet 지도와 뷰 상태(중심·배율·범위), EPSG:5186 ↔ WGS84 변환, 제주 범위 고정, 배경지도(브이월드) 켜고 끄기 | E5: 김재헌 | F5: 46240 | G5: 46244 | H5: =MAX(1,NETWORKDAYS(F5,G5,인덱스!$B$41:$B$47)) | I5: 완료 | J5: SFR-007-01, NFR-009-01 | K5: SCR-001 | L5: components/MapPane
A6: FE-005 | B6: 조회 | C6: 조회 조건(지역·기간·등급) | D6: AnalysisFilter·RegionSelect·MonthPicker: 읍면동 선택, 분석 기간, 등급, 지도 범위 필터 | E6: 정하늘 | F6: 46241 | G6: 46246 | H6: =MAX(1,NETWORKDAYS(F6,G6,인덱스!$B$41:$B$47)) | I6: 완료 | J6: SFR-007-03 | K6: SCR-001 | L6: components/AnalysisFilter, RegionSelect, MonthPicker
A7: FE-006 | B7: 지도 | C7: 해안선·지질·재해위험지구 GeoJSON 레이어 | D7: 수치지질도에서 만든 해안선(coast)과 지질 폴리곤, 재해위험지구를 GeoJsonLayer 로 표시, 속성 툴팁 | E7: 김재헌 | F7: 46245 | G7: 46246 | H7: =MAX(1,NETWORKDAYS(F7,G7,인덱스!$B$41:$B$47)) | I7: 완료 | J7: SFR-007-01 | K7: SCR-001 | L7: components/layers/GeoJsonLayer | M7: 망 분리 환경에서는 배경지도 없이 해안선이 위치감을 대신
A8: FE-007 | B8: 지도 | C8: 격자 셀 렌더링(GridCellsLayer) | D8: 셀을 남서 꼭짓점 + 셀 크기로 그리는 방식, 100 m 셀은 단순화 끔(smoothFactor 0), 10 m 셀은 1.02 겹침으로 흰 틈 제거, 화면 안 셀만 그리기 | E8: 김재헌 | F8: 46247 | G8: 46253 | H8: =MAX(1,NETWORKDAYS(F8,G8,인덱스!$B$41:$B$47)) | I8: 완료 | J8: SFR-001-01, NFR-001-01 | K8: SCR-004 | L8: components/layers/GridCellsLayer
A9: FE-008 | B9: 조회 | C9: 조회 결과(도넛·순위 목록) | D9: 등급 분포 도넛(GradeDonut), 위험 후보지역 순위 목록(RankPanel)·페이징, 목록 ↔ 지도 핀 연동 | E9: 정하늘 | F9: 46247 | G9: 46253 | H9: =MAX(1,NETWORKDAYS(F9,G9,인덱스!$B$41:$B$47)) | I9: 완료 | J9: SFR-003-02, SFR-003-05 | K9: SCR-002 | L9: components/GradeDonut, RankPanel
A10: FE-009 | B10: 지도 | C10: InSAR 지반 변위 레이어 | D10: 2 km 블록 타일(insar10m/{x}_{y}.json) 지연 로딩, 배율에 따라 10 m / 100 m 집계 셀 전환, 발산형 배색(변위속도), 툴팁(변위속도·누적변위) | E10: 김재헌 | F10: 46254 | G10: 46259 | H10: =MAX(1,NETWORKDAYS(F10,G10,인덱스!$B$41:$B$47)) | I10: 완료 | J10: SFR-002-01, SFR-003-01 | K10: SCR-004 | L10: insar 레이어 설정, GridCellsLayer
A11: FE-010 | B11: 조회 | C11: 구역 상세·판단 근거 | D11: DetailPanel: 인자별 기여도 막대·점수, 대표 변위값, 원인 후보 Top-N, 권장 점검 방식 | E11: 정하늘 | F11: 46254 | G11: 46258 | H11: =MAX(1,NETWORKDAYS(F11,G11,인덱스!$B$41:$B$47)) | I11: 완료 | J11: SFR-006-03, SFR-003-04 | K11: SCR-003 | L11: components/DetailPanel
A12: FE-011 | B12: 지도 | C12: 지하시설물 레이어(관로·굴착) | D12: 관로 GeoJSON 스타일(연한·관종), 굴착 공사 건수 클러스터(CountClusterLayer, 동 단위 집계) | E12: 정하늘 | F12: 46259 | G12: 46261 | H12: =MAX(1,NETWORKDAYS(F12,G12,인덱스!$B$41:$B$47)) | I12: 완료 | J12: SFR-001-02, SFR-004-02 | K12: SCR-005 | L12: components/layers/CountClusterLayer | M12: 굴착 허가는 좌표가 없어 동 단위
A13: FE-012 | B13: 지도 | C13: 위험격자(CSI) 레이어·등급 라벨 | D13: 100 m 격자 CSI 점수·등급 A–E 채색, 배율 15 이상에서 셀 라벨(`CSI 83`, 700개 상한), 지반 변위 레이어와 같은 층이라 배타 표시(exclusiveWith) | E13: 김재헌 | F13: 46260 | G13: 46262 | H13: =MAX(1,NETWORKDAYS(F13,G13,인덱스!$B$41:$B$47)) | I13: 완료 | J13: SFR-001-05, SFR-003-03 | K13: SCR-002, SCR-004 | L13: csi 레이어 설정
A14: FE-013 | B14: 지도 | C14: 침하 사고이력 레이어·사고 관리 화면 | D14: 사고 지점 마커·툴팁(IncidentPointsLayer), 관리자용 사고 이력 등록·수정 화면(IncidentPage) | E14: 정하늘 | F14: 46262 | G14: 46267 | H14: =MAX(1,NETWORKDAYS(F14,G14,인덱스!$B$41:$B$47)) | I14: 완료 | J14: SFR-001-02 | K14: SCR-006, SCR-012 | L14: components/layers/IncidentPointsLayer, IncidentPage, lib/incidents
A15: FE-014 | B15: 지도 | C15: 그리기 성능 정리 | D15: 화면 범위 밖 셀 생략, 타일 캐시(블록 단위), 배율 전환 시 재그리기 최소화, 10 m 셀 25만 개 기준 끊김 없는지 확인 | E15: 김재헌 | F15: 46265 | G15: 46267 | H15: =MAX(1,NETWORKDAYS(F15,G15,인덱스!$B$41:$B$47)) | I15: 완료 | J15: NFR-001-01 | K15: SCR-004 | L15: lib/useLayerSource
A16: FE-015 | B16: 패널 | C16: 레이어 패널·범례 | D16: 레이어 켜고 끄기, 순서(z-order), 배경지도 켜면 숨는 레이어(hideWithBasemap), 레이어 설정에서 범례 자동 생성 | E16: 김재헌 | F16: 46268 | G16: 46272 | H16: =MAX(1,NETWORKDAYS(F16,G16,인덱스!$B$41:$B$47)) | I16: 완료 | J16: SFR-007-01 | K16: SCR-001 | L16: components/LayerPanel, components/Legend
A17: FE-016 | B17: 조회 | C17: 위험 징후 알림 | D17: AlertPanel: 직전 분석 대비 신규·상향 구역 목록, 배지에서 바로 걸러 보기 | E17: 정하늘 | F17: 46268 | G17: 46269 | H17: =MAX(1,NETWORKDAYS(F17,G17,인덱스!$B$41:$B$47)) | I17: 완료 | J17: SFR-008-05 | K17: SCR-007 | L17: components/AlertPanel
A18: FE-017 | B18: 내보내기 | C18: 공간정보 내보내기·리포트 | D18: GeoJSON·CSV·Excel·PDF(국문 글꼴 내장) 내보내기, 메타데이터 6종 표기, 조회 조건 그대로 리포트 생성 | E18: 정하늘 | F18: 46272 | G18: 46275 | H18: =MAX(1,NETWORKDAYS(F18,G18,인덱스!$B$41:$B$47)) | I18: 완료 | J18: SFR-007-04, SFR-007-05, NFR-008-01 | K18: SCR-008, SCR-009 | L18: components/ExportActions, lib/exporters, lib/pdfFont | M18: SHP·GeoTIFF 는 서버 연계 뒤
A19: FE-018 | B19: 조회 | C19: 기간 설정(RunBar)·기간별 점수 전환 | D19: 관측 연도 구간(from–to)을 고르면 미리 계산된 점수 파일(out/scores/{from}-{to}.json)로 바꿔 그리기, 위치·기간 칩 | E19: 김재헌 | F19: 46273 | G19: 46275 | H19: =MAX(1,NETWORKDAYS(F19,G19,인덱스!$B$41:$B$47)) | I19: 완료 | J19: SFR-007-02 | K19: SCR-001, SCR-002 | L19: App(RunBar), lib/runHistory | M19: 타임슬라이더는 시계열 InSAR 입수 뒤(예정)
A20: FE-019 | B20: 구조 | C20: 워크스페이스·레이어 설정(manifest) 로딩 | D20: orgs/{org}/workspaces/{ws}/workspace.json(순서·가시성·스타일)과 layers/{layer}/manifest.json 을 읽어 레이어를 동적으로 구성, 레이어 종류별 렌더러 맵(grid-cells·geojson·incident-points·count-cluster·risk-index) | E20: 김재헌 | F20: 46276 | G20: 46282 | H20: =MAX(1,NETWORKDAYS(F20,G20,인덱스!$B$41:$B$47)) | I20: 완료 | J20: SFR-007-01, NFR-002-02 | K20: SCR-001 | L20: lib/workspace, lib/useLayerSource, components/layers/* | M20: 하드코딩 레이어 제거
A21: FE-020 | B21: 관리자 | C21: 권한·작업 기록 화면 | D21: 레이어 권한·파일 내보내기 권한(AdminPage, lib/perms), 작업 기록(AuditPage, lib/audit): 내보내기·사고 변경·권한 변경 자동 기록, 엑셀 내려받기 | E21: 정하늘 | F21: 46276 | G21: 46281 | H21: =MAX(1,NETWORKDAYS(F21,G21,인덱스!$B$41:$B$47)) | I21: 완료 | J21: SFR-008-02, NFR-003-05 | K21: SCR-010, SCR-011, SCR-013 | L21: components/AdminPage, AuditPage, lib/perms, lib/audit | M21: 브라우저 저장 — 감사 증적은 서버 저장으로 옮겨야 함(예정)
A22: FE-021 | B22: 화면 | C22: 도움말·산정 모델 설명 | D22: 산정 모델(가중치·등급 기준)과 자료 한계(가속도 미산출, 동 단위 굴착)를 화면 안에서 설명 | E22: 정하늘 | F22: 46282 | G22: 46282 | H22: =MAX(1,NETWORKDAYS(F22,G22,인덱스!$B$41:$B$47)) | I22: 완료 | J22: NFR-007-02 | K22: SCR-003 | L22: Header 도움말
A23: FE-022 | B23: 구조 | C23: 표시 형식 해석기(layerStyle) | D23: manifest 의 classes(구간)·categories(범주)·tooltip 템플릿·legend 를 해석해 색·라벨·툴팁을 만드는 공용 모듈과 단위 테스트 | E23: 김재헌 | F23: 46283 | G23: 46287 | H23: =MAX(1,NETWORKDAYS(F23,G23,인덱스!$B$41:$B$47)) | I23: 완료 | J23: SFR-007-01, NFR-007-02 | K23: SCR-001 | L23: lib/layerStyle, layerStyle.test
A24: FE-023 | B24: 화면 | C24: 분석 실행 기록·기간 설정 동작 | D24: 실행 이력(runHistory) 저장과 복원, 기간을 바꿨을 때 결과·알림·내보내기가 함께 바뀌는지 정리 | E24: 정하늘 | F24: 46283 | G24: 46286 | H24: =MAX(1,NETWORKDAYS(F24,G24,인덱스!$B$41:$B$47)) | I24: 완료 | J24: SFR-007-02 | K24: SCR-001 | L24: lib/runHistory
A25: FE-024 | B25: 품질 | C25: 단위 테스트 정비(vitest) | D25: 컴포넌트·lib 단위 테스트 177건, 커버리지 93 %, 지도·레이어 컴포넌트는 E2E 로 보완 | E25: 정하늘 | F25: 46287 | G25: 46294 | H25: =MAX(1,NETWORKDAYS(F25,G25,인덱스!$B$41:$B$47)) | I25: 완료 | J25: - | K25: - | L25: src/**/*.test.ts(x), vitest.config
A26: FE-025 | B26: 검증 | C26: 구조 전환 검증 | D26: 전환 전·후 화면 5장면을 픽셀 단위로 비교, 28개 기간 × 1,179 구역 점수가 이전 계산과 같은지 확인 | E26: 김재헌 | F26: 46288 | G26: 46294 | H26: =MAX(1,NETWORKDAYS(F26,G26,인덱스!$B$41:$B$47)) | I26: 완료 | J26: NFR-007-02 | K26: - | L26: 비교 스크립트, 캡처 PNG
A27: FE-026 | B27: 구조 | C27: FE 저장소 분리·strict TypeScript 전환 | D27: 프로토타입에서 jeju-ai-saas-fe 로 분리, strict TS, src/types.ts, OpenAPI 에서 타입 생성(openapi-typescript → api/schema.d.ts), API 호출을 BE 중계 API 로 전환 | E27: 김재헌 | F27: 46295 | G27: 46302 | H27: =MAX(1,NETWORKDAYS(F27,G27,인덱스!$B$41:$B$47)) | I27: 완료 | J27: NFR-002-02, NFR-005-01 | K27: - | L27: innopam/jeju-ai-saas-fe, src/types.ts, src/api/schema.d.ts | M27: BE 분리(BE 시트)와 같은 주
A28: FE-027 | B28: 화면 | C28: 브라우저 호환·반응형 점검 | D28: Chrome·Edge·Safari 확인, 좁은 폭에서 드로어·패널 배치 | E28: 정하늘 | F28: 46295 | G28: 46296 | H28: =MAX(1,NETWORKDAYS(F28,G28,인덱스!$B$41:$B$47)) | I28: 완료 | J28: NFR-009-01 | K28: SCR-001 | L28: -
A29: FE-028 | B29: 품질 | C29: 품질 검사 1단계: 도구 고정·훅·비밀값 차단 | D29: mise(node·lefthook·gitleaks·prettier 버전 고정), lefthook(pre-commit 비밀값·린트, pre-push typecheck·테스트), .gitleaks.toml(브이월드 키 규칙·.env 경로) | E29: 정하늘 | F29: 46297 | G29: 46301 | H29: =MAX(1,NETWORKDAYS(F29,G29,인덱스!$B$41:$B$47)) | I29: 완료 | J29: NFR-003-01 | K29: - | L29: mise.toml, lefthook.yml, .gitleaks.toml
A30: FE-029 | B30: 품질 | C30: 품질 검사 2단계: 린트·접근성 규칙 | D30: ESLint(typescript-eslint 타입 규칙·react·react-hooks·jsx-a11y strict) 61건과 stylelint 836건을 0으로, markdownlint·actionlint | E30: 정하늘 | F30: 46302 | G30: 46307 | H30: =MAX(1,NETWORKDAYS(F30,G30,인덱스!$B$41:$B$47)) | I30: 완료 | J30: NFR-009-01 | K30: - | L30: eslint.config, stylelint.config | M30: 색 대비 위반은 디자인 토큰 색이라 요소 단위 제외(FE #5)
A31: FE-030 | B31: 배포 | C31: FE 이미지·API 프록시 | D31: nginx 이미지(Dockerfile), nginx.conf.template 로 /api/ 를 API_UPSTREAM 에 프록시, 정적 캐시 헤더 | E31: 김재헌 | F31: 46303 | G31: 46307 | H31: =MAX(1,NETWORKDAYS(F31,G31,인덱스!$B$41:$B$47)) | I31: 완료 | J31: NFR-005-01 | K31: - | L31: Dockerfile, nginx.conf.template
A32: FE-031 | B32: 구조 | C32: 예시 레이어(동 중심점) 추가 | D32: 레이어를 설정 파일만으로 추가할 수 있는지 확인하는 예시 레이어와 기본 권한(DEFAULT_PERMS) 등록 | E32: 김재헌 | F32: 46308 | G32: 46308 | H32: =MAX(1,NETWORKDAYS(F32,G32,인덱스!$B$41:$B$47)) | I32: 완료 | J32: NFR-002-02 | K32: SCR-010 | L32: orgs/jeju/layers/dong-centers
A33: FE-032 | B33: 품질 | C33: E2E·접근성·웹표준·시각 회귀 | D33: puppeteer → Playwright 전환(12건 유지), 가짜 API 서버(e2e/fixture-server), axe 접근성 9장면, html-validate 웹표준, 시각 회귀 8장면 기준 PNG | E33: 정하늘 | F33: 46308 | G33: 46317 | H33: =MAX(1,NETWORKDAYS(F33,G33,인덱스!$B$41:$B$47)) | I33: 진행 | J33: NFR-009-01 | K33: SCR-001–SCR-013 | L33: e2e/*.spec.ts, playwright.config, e2e/__snapshots__ | M33: 종료일은 예정일. amd64 러너 기준 PNG 는 CI 게이트 뒤
A34: FE-033 | B34: 정리 | C34: 컴포넌트 분리·훅 정리 | D34: MapPane 에 몰린 로직을 레이어 컴포넌트와 훅으로 분리, 리렌더 줄이기 | E34: 김재헌 | F34: 46309 | G34: 46310 | H34: =MAX(1,NETWORKDAYS(F34,G34,인덱스!$B$41:$B$47)) | I34: 완료 | J34: NFR-009-01 | K34: - | L34: components/layers/*, lib/*
A35: FE-034 | B35: 패널 | C35: 레이어 순서·표시 편집 UI 설계 | D35: 워크스페이스 설정의 순서·가시성·스타일을 화면에서 바꾸는 흐름 설계, 저장 API 요건을 BE 와 합의 | E35: 김재헌 | F35: 46311 | G35: 46316 | H35: =MAX(1,NETWORKDAYS(F35,G35,인덱스!$B$41:$B$47)) | I35: 진행 | J35: SFR-007-01, SFR-007-03 | K35: SCR-001, SCR-010 | L35: 설계 메모 | M35: 종료일은 예정일
A36: FE-035 | B36: 패널 | C36: 레이어 순서·표시 편집 UI 구현 | D36: 드래그로 순서 바꾸기, 가시성·스타일 편집, 변경 내용을 워크스페이스 설정으로 저장(BE API) | E36: 김재헌 | F36: 46317 | G36: 46323 | H36: =MAX(1,NETWORKDAYS(F36,G36,인덱스!$B$41:$B$47)) | I36: 예정 | J36: SFR-007-01, SFR-007-03 | K36: SCR-001, SCR-010 | L36: - | M36: BE 의 워크스페이스 저장 API 필요
A37: FE-036 | B37: 품질 | C37: FE CI 게이트·야간 검사 | D37: ci.yml: push 마다 비밀값·린트·typecheck·테스트·E2E → develop 만 이미지 push, nightly.yml: Lighthouse·k6·ZAP·trivy 결과 보고 | E37: 정하늘 | F37: 46318 | G37: 46323 | H37: =MAX(1,NETWORKDAYS(F37,G37,인덱스!$B$41:$B$47)) | I37: 예정 | J37: NFR-001-01, NFR-003-01 | K37: - | L37: GitHub 이슈 FE #1, #2
A38: FE-037 | B38: 구조 | C38: 메타데이터 DB 전환에 맞춘 FE 변경 | D38: 조직·워크스페이스·레이어 목록을 파일 catalog 대신 DB API 로 읽기, 관리 화면에서 생성·수정·삭제 | E38: 김재헌 | F38: 46324 | G38: 46330 | H38: =MAX(1,NETWORKDAYS(F38,G38,인덱스!$B$41:$B$47)) | I38: 예정 | J38: SFR-008-01, SFR-008-02 | K38: SCR-010 | L38: - | M38: BE DB 전환과 함께
A39: FE-038 | B39: 보안 | C39: nginx 보안 응답 헤더 | D39: CSP·HSTS·X-Content-Type-Options 등을 FE 응답에 추가, E2E 로 확인 | E39: 정하늘 | F39: 46324 | G39: 46325 | H39: =MAX(1,NETWORKDAYS(F39,G39,인덱스!$B$41:$B$47)) | I39: 예정 | J39: NFR-003-01 | K39: - | L39: GitHub 이슈 FE #3
A40: FE-039 | B40: 품질 | C40: 색 대비 토큰 결정 반영·리팩터 | D40: WCAG AA 4.5:1 미달 색 결정 반영(FE #5), set-state-in-effect 예외 4곳 리팩터(FE #6), ESLint 10(FE #7) | E40: 정하늘 | F40: 46328 | G40: 46330 | H40: =MAX(1,NETWORKDAYS(F40,G40,인덱스!$B$41:$B$47)) | I40: 예정 | J40: NFR-009-01 | K40: - | L40: GitHub 이슈 FE #5, #6, #7
...

Sheet BE
A1: ID | B1: 영역 | C1: 작업명 | D1: 작업 내용 | E1: 담당자 | F1: 시작일 | G1: 종료일 | H1: 공수(일) | I1: 상태 | J1: 관련 요구사항ID | K1: 관련 화면ID | L1: 산출물 | M1: 비고
A2: BE-001 | B2: 자료 | C2: 원본 자료 조사·좌표계 정리 | D2: InSAR 10 m 산출물, 상하수도 관로, 도로점용(굴착) 허가대장, 지반침하 사고이력, 지질도, 재해위험지구를 수집하고 EPSG:5186 으로 통일, 자료별 단위·관측기간 표 | E2: 김규영 | F2: 46237 | G2: 46239 | H2: =MAX(1,NETWORKDAYS(F2,G2,인덱스!$B$41:$B$47)) | I2: 완료 | J2: SFR-001-02, SFR-001-03 | K2: - | L2: docs/data-sources
A3: BE-002 | B3: 자료 | C3: 원본 자료 품질 점검·결측 처리 | D3: 중복·결측·좌표 이상값 점검, 사고이력 주소 정리, 기준 범위(제주 전역) 밖 자료 제외 | E3: 김규영 | F3: 46240 | G3: 46241 | H3: =MAX(1,NETWORKDAYS(F3,G3,인덱스!$B$41:$B$47)) | I3: 완료 | J3: SFR-001-03, NFR-007-01 | K3: - | L3: pipeline/gislib
A4: BE-003 | B4: 격자 | C4: 10 m 표준 격자·100 m 집계 셀 생성 | D4: 제주 전역 10 m 셀과 셀 ID 체계, 100 m 집계 셀, 2 km 블록 타일 분할(insar10m/{x}_{y}.json)과 100 m 집계 파일(insar_cells.json) | E4: 조혜인 | F4: 46244 | G4: 46247 | H4: =MAX(1,NETWORKDAYS(F4,G4,인덱스!$B$41:$B$47)) | I4: 완료 | J4: SFR-001-01, NFR-007-03 | K4: SCR-004 | L4: pipeline/build_data.py
A5: BE-004 | B5: 자료 | C5: 인벤토리 격자 바인딩 | D5: 관로·사고·지질·재해위험지구를 100 m 격자에 결합(gislib), 셀 ID 를 조인 키로 하는 속성 스택 | E5: 김규영 | F5: 46248 | G5: 46254 | H5: =MAX(1,NETWORKDAYS(F5,G5,인덱스!$B$41:$B$47)) | I5: 완료 | J5: SFR-004-01, SFR-004-02 | K5: SCR-005 | L5: pipeline/gislib.py
A6: BE-005 | B6: 자료 | C6: 굴착 허가 지오코딩 | D6: 허가대장에 좌표가 없어 문서 제목·점용지에서 법정동명을 뽑아 동 단위 집계(1,099건 / 19개 동, 2023–2025) | E6: 전재환 | F6: 46255 | G6: 46259 | H6: =MAX(1,NETWORKDAYS(F6,G6,인덱스!$B$41:$B$47)) | I6: 완료 | J6: SFR-001-02 | K6: SCR-005 | L6: pipeline/geocode_excavation.py | M6: 좌표가 있는 대장 입수 시 셀 단위로 전환
A7: BE-006 | B7: 자료 | C7: 행정경계 최근접 배정·지역 목록 | D7: 읍면동 경계 자료가 없어 자연재해저감 종합계획의 지명 403개를 기준점으로 셀을 최근접 배정, regions.json | E7: 전재환 | F7: 46260 | G7: 46261 | H7: =MAX(1,NETWORKDAYS(F7,G7,인덱스!$B$41:$B$47)) | I7: 완료 | J7: SFR-001-03 | K7: SCR-001 | L7: csi-factors/regions.json | M7: 경계 부근 셀은 실제 행정구역과 다를 수 있음
A8: BE-007 | B8: 지수 | C8: 복합 위험지수(CSI) 산정 로직 | D8: 7개 인자 가중합(30/22/14/12/10/7/5), 등급 구간(E 85·D 70·C 55·B 40·A 0), 상위 5 % 긴급 정밀탐측 대상 표시 | E8: 조혜인 | F8: 46262 | G8: 46267 | H8: =MAX(1,NETWORKDAYS(F8,G8,인덱스!$B$41:$B$47)) | I8: 완료 | J8: SFR-001-04, SFR-001-05, SFR-003-03 | K8: SCR-002 | L8: layers/csi/logic/main.py | M8: 지하수위·포트홀·교통량 인자는 자료 미확보로 제외
A9: BE-008 | B9: 지수 | C9: 기간별 점수 사전 계산 | D9: 관측 연도 구간 28개(from–to)에 대해 점수·등급을 미리 계산해 out/scores/{from}-{to}.json, 모델 정보 out/model.json | E9: 조혜인 | F9: 46268 | G9: 46269 | H9: =MAX(1,NETWORKDAYS(F9,G9,인덱스!$B$41:$B$47)) | I9: 완료 | J9: SFR-001-04, SFR-007-02 | K9: SCR-002 | L9: out/scores/, out/model.json
A10: BE-009 | B10: 구조 | C10: 워크스페이스·레이어 자료 구조 | D10: orgs/{org}/org.json, workspaces/{ws}/workspace.json(순서·가시성·스타일), layers/{layer}/manifest.json(kind·styles·source·levels·tiles 색인), build_catalog.py 로 catalog 생성 | E10: 유소운 | F10: 46272 | G10: 46275 | H10: =MAX(1,NETWORKDAYS(F10,G10,인덱스!$B$41:$B$47)) | I10: 완료 | J10: NFR-002-02, NFR-007-02 | K10: - | L10: tools/build_catalog.py, data/orgs/jeju/**
A11: BE-010 | B11: 지수 | C11: 지수 레이어 계약·격리 실행 | D11: index.runtime/entry/inputs/params/out 계약, run_index.py 가 로직을 컨테이너(python:3.12-alpine, --network none, 읽기 전용, --cap-drop ALL, 비root, 메모리 1 g·CPU 1·pids 128)에서 실행, 입력은 /in 읽기 전용 | E11: 최성민 | F11: 46276 | G11: 46281 | H11: =MAX(1,NETWORKDAYS(F11,G11,인덱스!$B$41:$B$47)) | I11: 완료 | J11: SFR-006-01, NFR-003-02 | K11: - | L11: pipeline/run_index.py
A12: BE-011 | B12: 지수 | C12: 샌드박스 탈출 시험·출력 검증 | D12: 네트워크·DNS·쓰기 차단과 uid 확인, 출력은 JSON 만·크기 상한·링크 금지 검증 뒤 out/ 원자적 교체 | E12: 최성민 | F12: 46282 | G12: 46283 | H12: =MAX(1,NETWORKDAYS(F12,G12,인덱스!$B$41:$B$47)) | I12: 완료 | J12: NFR-003-02 | K12: - | L12: pipeline/tests/test_run_index.py
A13: BE-012 | B13: 자료 | C13: 데이터 빌드 재현성 | D13: build_data.py 가 orgs/jeju/layers/** 로 산출하고 catalog 까지 만들도록, 산출 자료를 저장소에 포함, README 에 절차 | E13: 김규영 | F13: 46286 | G13: 46287 | H13: =MAX(1,NETWORKDAYS(F13,G13,인덱스!$B$41:$B$47)) | I13: 완료 | J13: NFR-007-02 | K13: - | L13: README, data/
A14: BE-013 | B14: API | C14: BE 저장소 분리·API 골격 | D14: jeju-ai-saas-be 로 분리, Node 24 + Fastify 5, @fastify/swagger 로 OpenAPI 생성, openapi.json 을 계약으로 고정(openapi:check) | E14: 유소운 | F14: 46288 | G14: 46295 | H14: =MAX(1,NETWORKDAYS(F14,G14,인덱스!$B$41:$B$47)) | I14: 완료 | J14: NFR-002-02, NFR-005-01 | K14: - | L14: api/src/app.ts, openapi.json | M14: FE 분리(FE 시트)와 같은 주
A15: BE-014 | B15: 저장소 | C15: 객체 저장소(SeaweedFS S3)·동기화 CLI | D15: S3 호환 저장소 compose(필러 UI 127.0.0.1:8888), storage push/pull CLI(md5·ETag 로 바뀐 것만), 버킷 자료 구조 문서 | E15: 전재환 | F15: 46296 | G15: 46297 | H15: =MAX(1,NETWORKDAYS(F15,G15,인덱스!$B$41:$B$47)) | I15: 완료 | J15: SFR-004-04, NFR-003-04 | K15: - | L15: docker-compose.yml, api/src/cli/storage.ts
A16: BE-015 | B16: API | C16: catalog·workspace·layer files API | D16: /api/catalog, /api/orgs/:org/workspaces/:ws, /api/orgs/:org/layers/:layer/files/*(ETag/304, JSON·GeoJSON 만, 경로 검증), /api/health, /api/openapi.json | E16: 유소운 | F16: 46301 | G16: 46303 | H16: =MAX(1,NETWORKDAYS(F16,G16,인덱스!$B$41:$B$47)) | I16: 완료 | J16: SFR-007-01, NFR-003-03 | K16: - | L16: api/src/catalog.ts, storage.ts, sync.ts
A17: BE-016 | B17: 배포 | C17: API 이미지·dev 배포 연동 | D17: Dockerfile, 환경 변수(S3 엔드포인트·버킷·자격), develop 이미지 push 워크플로, dev 에서 FE → API → 저장소 경로 확인 | E17: 전재환 | F17: 46307 | G17: 46308 | H17: =MAX(1,NETWORKDAYS(F17,G17,인덱스!$B$41:$B$47)) | I17: 완료 | J17: NFR-005-01 | K17: - | L17: api/Dockerfile, .github/workflows | M17: 클러스터 쪽은 DevOps 시트
A18: BE-017 | B18: 품질 | C18: 품질 검사 1–2단계: 도구·훅·린트 | D18: mise(node·python·lefthook·gitleaks·ruff·yamllint·hadolint·actionlint·pip-audit), lefthook, .gitleaks.toml, API ESLint 타입 규칙·파이프라인 ruff 지적 전부 수정, 커버리지 하한 70 %(실측 99/94/100) | E18: 최성민 | F18: 46309 | G18: 46311 | H18: =MAX(1,NETWORKDAYS(F18,G18,인덱스!$B$41:$B$47)) | I18: 완료 | J18: NFR-003-01 | K18: - | L18: mise.toml, lefthook.yml, api/eslint.config.js, pipeline/pyproject.toml | M18: zip(strict=True) 로 길이 불일치 시 오류
A19: BE-018 | B19: 품질 | C19: 품질 검사 3단계: 통합 테스트·CI 게이트·야간 검사 | D19: 실제 SeaweedFS 통합 테스트 16개(전용 compose), 합성 자료 시드, ci.yml(checks·integration·pipeline → develop 만 build-push, semgrep), nightly.yml(k6·ZAP·trivy 보고), @fastify/helmet 헤더 | E19: 최성민 | F19: 46314 | G19: 46317 | H19: =MAX(1,NETWORKDAYS(F19,G19,인덱스!$B$41:$B$47)) | I19: 진행 | J19: NFR-003-01, NFR-001-01 | K19: - | L19: .github/workflows/ci.yml, nightly.yml, api/test/integration | M19: 종료일은 예정일. 설정 결정 4건(BE #2) 대기
A20: BE-019 | B20: 품질 | C20: 품질 게이트 마무리 | D20: 설정 결정 4건 반영(BE #2), 러너에서 nightly.yml 실제 실행 확인(BE #1), 깨끗한 클론 재현 | E20: 최성민 | F20: 46318 | G20: 46321 | H20: =MAX(1,NETWORKDAYS(F20,G20,인덱스!$B$41:$B$47)) | I20: 예정 | J20: NFR-003-01 | K20: - | L20: GitHub 이슈 BE #1, #2
A21: BE-020 | B21: 인증 | C21: 로그인·인증 API | D21: ID/비밀번호(해시 저장) 또는 OIDC 연동 선택, 세션 쿠키(HttpOnly·SameSite), 역할 3종, 로그인 시도 제한, 인증 필요 경로 보호 | E21: 전재환 | F21: 46322 | G21: 46329 | H21: =MAX(1,NETWORKDAYS(F21,G21,인덱스!$B$41:$B$47)) | I21: 예정 | J21: SFR-008-02, NFR-003-01 | K21: SCR-010 | L21: - | M21: FE 로그인 화면과 함께. SSO 연계는 발주처 환경 확인 뒤
A22: BE-021 | B22: DB | C22: 메타데이터 DB 설계 | D22: PostgreSQL(+PostGIS) 스키마: 조직·워크스페이스·레이어·레이어 버전·권한·사용자·작업 기록, 파일 catalog 와의 대응표, 마이그레이션 도구 선정 | E22: 유소운 | F22: 46330 | G22: 46332 | H22: =MAX(1,NETWORKDAYS(F22,G22,인덱스!$B$41:$B$47)) | I22: 예정 | J22: SFR-008-01, SFR-008-03 | K22: - | L22: 설계 문서 | M22: DB 운영(복제·백업)은 DevOps 시트
A23: BE-022 | B23: DB | C23: 조직·워크스페이스·레이어 DB 전환 | D23: CRUD API(조직·워크스페이스·레이어·순서·스타일), 파일 catalog → DB 이관 스크립트, 권한 검사(조직 소유·타 조직 읽기), 레이어 파일은 계속 객체 저장소 | E23: 유소운 | F23: 46335 | G23: 46343 | H23: =MAX(1,NETWORKDAYS(F23,G23,인덱스!$B$41:$B$47)) | I23: 예정 | J23: SFR-008-01, SFR-008-02, NFR-002-02 | K23: SCR-010 | L23: - | M23: FE 관리 화면 전환과 함께
A24: BE-023 | B24: DB | C24: 작업 기록(감사) 저장 API | D24: 내보내기·사고 변경·권한 변경 기록 저장·조회·필터, 보존 기간 | E24: 전재환 | F24: 46344 | G24: 46345 | H24: =MAX(1,NETWORKDAYS(F24,G24,인덱스!$B$41:$B$47)) | I24: 예정 | J24: NFR-003-05 | K24: SCR-013 | L24: -
A25: BE-024 | B25: 타일 | C25: 벡터 타일 전환 조사 | D25: JSON 블록 타일 → MBTiles 또는 PMTiles 비교: tippecanoe 변환 용량·시간, 제공 방식(martin 타일 서버 vs S3 range 요청으로 PMTiles 직접), 캐시·갱신 절차 | E25: 조혜인 | F25: 46346 | G25: 46350 | H25: =MAX(1,NETWORKDAYS(F25,G25,인덱스!$B$41:$B$47)) | I25: 예정 | J25: NFR-001-01, NFR-008-01 | K25: SCR-004 | L25: 조사 메모 | M25: FE 렌더링 평가와 같이
A26: BE-025 | B26: 타일 | C26: 벡터 타일 파이프라인·제공 | D26: build_data 산출(10 m 격자·InSAR·100 m 집계)을 벡터 타일로 변환해 객체 저장소에 올리고 타일 API 또는 서버 구성, manifest source 에 tiles 종류 추가, JSON 타일과 병행 | E26: 조혜인 | F26: 46351 | G26: 46358 | H26: =MAX(1,NETWORKDAYS(F26,G26,인덱스!$B$41:$B$47)) | I26: 예정 | J26: SFR-002-01, NFR-001-01 | K26: SCR-004 | L26: -
A27: BE-026 | B27: 자료 | C27: 시계열 InSAR 적재 | D27: 시계열 변위 입수 뒤 가속도 인자 산출(load_insar 2차 항), 기간별 점수에 반영 | E27: 김규영 | F27: 46359 | G27: 46364 | H27: =MAX(1,NETWORKDAYS(F27,G27,인덱스!$B$41:$B$47)) | I27: 예정 | J27: SFR-002-01, SFR-007-02 | K27: SCR-004 | L27: - | M27: 자료 입수 뒤

Sheet DevOps
A1: ID | B1: 영역 | C1: 작업명 | D1: 작업 내용 | E1: 담당자 | F1: 시작일 | G1: 종료일 | H1: 공수(일) | I1: 상태 | J1: 관련 요구사항ID | K1: 관련 화면ID | L1: 산출물 | M1: 비고
A2: DEVOPS-001 | B2: 가상화 | C2: Proxmox 노드 정리 | D2: 호스트명 pve-1 통일, APT 저장소를 no-subscription 으로 교체 | E2: 박가람 | F2: 46301 | G2: 46301 | H2: =MAX(1,NETWORKDAYS(F2,G2,인덱스!$B$41:$B$47)) | I2: 완료 | J2: NFR-005-02 | K2: - | L2: docs/history/2026/10/06/01
A3: DEVOPS-002 | B3: 클러스터 | C3: 클러스터 구축 준비 | D3: mise 로 도구 설치, Proxmox API 토큰, OpenTofu(VM)·Talos(머신 설정·부트스트랩)·Cilium(values·LB IP 풀) 코드 작성, 저장소 첫 커밋과 비밀값 제외 규칙 | E3: 박가람 | F3: 46301 | G3: 46301 | H3: =MAX(1,NETWORKDAYS(F3,G3,인덱스!$B$41:$B$47)) | I3: 완료 | J3: NFR-005-01 | K3: - | L3: tofu/, talos/, k8s/cilium/, 10/06/02–04
A4: DEVOPS-003 | B4: 클러스터 | C4: dev0 클러스터 부트스트랩 | D4: Talos VM 3대(컨트롤 플레인 1·워커 2) 생성, Kubernetes 부트스트랩, dev·stage 네임스페이스 | E4: 박가람 | F4: 46301 | G4: 46301 | H4: =MAX(1,NETWORKDAYS(F4,G4,인덱스!$B$41:$B$47)) | I4: 완료 | J4: NFR-005-01 | K4: - | L4: 10/06/05 | M4: 이후 10/09 에 6대로 확장
A5: DEVOPS-004 | B5: 스토리지 | C5: local-path 스토리지 | D5: 워커에 Talos 사용자 볼륨, local-path-provisioner 를 기본 StorageClass 로 설치 | E5: 박가람 | F5: 46301 | G5: 46301 | H5: =MAX(1,NETWORKDAYS(F5,G5,인덱스!$B$41:$B$47)) | I5: 완료 | J5: NFR-004-01 | K5: - | L5: k8s/storage/, 10/06/09
A6: DEVOPS-005 | B6: 접근 | C6: Tailscale 경유 API 접속·CA 교체 | D6: Tailscale 포트 전달과 전용 kubeconfig, 노출된 kubeconfig 를 무효화하려고 Kubernetes API CA 교체, CA 교체 이전 백업 삭제 | E6: 박가람 | F6: 46301 | G6: 46301 | H6: =MAX(1,NETWORKDAYS(F6,G6,인덱스!$B$41:$B$47)) | I6: 완료 | J6: NFR-003-01, NFR-003-04 | K6: - | L6: 10/06/12, 13, 18
A7: DEVOPS-006 | B7: 문서 | C7: C4 구조도·구축 보고서·백업 절차 | D7: dev0 C4 구조도(flowchart 로 교체), 로컬 Kubernetes 구축 보고서 두 판(공유용은 보안 사고 장·Tailscale 제외), 비밀 파일 백업 절차 문서 | E7: 박가람 | F7: 46301 | G7: 46301 | H7: =MAX(1,NETWORKDAYS(F7,G7,인덱스!$B$41:$B$47)) | I7: 완료 | J7: NFR-007-02 | K7: - | L7: docs/architecture/k8s-c4.md, docs/reports/, docs/operations/secrets-backup.md
A8: DEVOPS-007 | B8: 가상화 | C8: Proxmox 3노드 클러스터·VIP | D8: pve-1·2·3 클러스터 구성, pve-2·3 APT 교체·전체 업그레이드·재부팅, keepalived VIP 192.168.200.100, OpenTofu 접속 주소를 VIP 로, keepalived 설정 저장소 복사 | E8: 박가람 | F8: 46304 | G8: 46304 | H8: =MAX(1,NETWORKDAYS(F8,G8,인덱스!$B$41:$B$47)) | I8: 완료 | J8: NFR-004-01 | K8: - | L8: configs/keepalived/, 10/09/01–04, 28
A9: DEVOPS-008 | B9: 네트워크 | C9: 두 번째 망·corosync 2링크 | D9: 세 노드 nic1 을 두 번째 망(172.16.200.0/24, 별도 스위치)으로 연결, corosync 두 번째 링크·링크 전환 시험(선 뽑기), pve-1 vmbr0 포트 변경, 공유기 DHCP 범위 축소·호스트 주소 등록, interfaces 정리 | E9: 박가람 | F9: 46304 | G9: 46304 | H9: =MAX(1,NETWORKDAYS(F9,G9,인덱스!$B$41:$B$47)) | I9: 완료 | J9: NFR-004-01 | K9: - | L9: docs/architecture/proxmox-cluster.md, 10/09/06–12, 16, 29
A10: DEVOPS-009 | B10: 클러스터 | C10: 컨트롤 플레인 3대·워커 3대로 확장 | D10: 컨트롤 플레인 3대로 늘리고 k8s VM 을 노드별로 분산, 세 번째 워커 추가, VM 사양 상향(CP 4 GB, 워커 4 vCPU·8 GB), dev·stage 쿼터 재조정 | E10: 박가람 | F10: 46304 | G10: 46304 | H10: =MAX(1,NETWORKDAYS(F10,G10,인덱스!$B$41:$B$47)) | I10: 완료 | J10: NFR-004-02, NFR-002-01 | K10: - | L10: tofu/, k8s/namespaces/, 10/09/13–15, 33
A11: DEVOPS-010 | B11: 장애시험 | C11: 장애 시험 1차 | D11: pve-2 의 VM 강제 종료(호스트 장애), pve-1 업그레이드·재부팅 관찰, pve-2 재부팅으로 API VIP·LoadBalancer IP·etcd 리더 전환, k8s-cp-1 라이브 마이그레이션 왕복 | E11: 박가람 | F11: 46304 | G11: 46304 | H11: =MAX(1,NETWORKDAYS(F11,G11,인덱스!$B$41:$B$47)) | I11: 완료 | J11: NFR-004-01 | K11: - | L11: 10/09/14, 34, 35, 37
A12: DEVOPS-011 | B12: 접근 | C12: 관리 환경 Mac 이전 | D12: Mac 에서 tofu·talosctl·kubectl 동작 확인, pve-1 의 tofu 상태 파일·비밀 파일 삭제와 정리, 구조 문서·백업 절차 반영 | E12: 박가람 | F12: 46304 | G12: 46304 | H12: =MAX(1,NETWORKDAYS(F12,G12,인덱스!$B$41:$B$47)) | I12: 완료 | J12: NFR-003-04 | K12: - | L12: 10/09/17, 19, 20, 25, 26, 30
A13: DEVOPS-012 | B13: 접근 | C13: Tailscale 서브넷 라우터 3대·ACL | D13: pve-1·2·3 을 서브넷 라우터로(192.168.200.0/24 광고), 접근을 장비 3대로 제한, LAN 밖 접속·노드 장애 시 경로 전환 시험, serve 6443 제거 | E13: 박가람 | F13: 46304 | G13: 46304 | H13: =MAX(1,NETWORKDAYS(F13,G13,인덱스!$B$41:$B$47)) | I13: 완료 | J13: NFR-003-03 | K13: - | L13: 10/09/21–24
A14: DEVOPS-013 | B14: 보안 | C14: Proxmox 웹 TLS·백업 매체·PV 보호 방향 | D14: Proxmox 웹 TLS 를 앞단 nginx 로(VIP 인증서 미발급), 백업 매체 USB 결정, PV 보호는 앱 복제 + Longhorn(Proxmox 복제·HA 미사용) | E14: 박가람 | F14: 46304 | G14: 46304 | H14: =MAX(1,NETWORKDAYS(F14,G14,인덱스!$B$41:$B$47)) | I14: 완료 | J14: NFR-003-01, NFR-004-01 | K14: - | L14: 10/09/18, 27, 38
A15: DEVOPS-014 | B15: 스토리지 | C15: Longhorn 설치·시험 | D15: Longhorn 설치, 쓰기 속도(51 MB/s)·워커 장애 조치·메모리 시험, 유지 결정 | E15: 박가람 | F15: 46305 | G15: 46305 | H15: =MAX(1,NETWORKDAYS(F15,G15,인덱스!$B$41:$B$47)) | I15: 완료 | J15: NFR-004-01 | K15: - | L15: k8s/longhorn/values.yaml, 10/10/01
A16: DEVOPS-015 | B16: 문서 | C16: 할 일 체계 정비 | D16: docs/history 날짜 폴더·순번, works.md → .ai-workflow/works(todo·doing·done), 전역 번호 W1–W62, 에이전트 7개로 인프라 현황 조사·개선 후보 등록·3차 검토, 결정 필요 열 | E16: 박가람 | F16: 46305 | G16: 46305 | H16: =MAX(1,NETWORKDAYS(F16,G16,인덱스!$B$41:$B$47)) | I16: 완료 | J16: - | K16: - | L16: .ai-workflow/works/main.md, 10/10/02–09, 24, 38
... A18: DEVOPS-017 | B18: 관측 | C18: metrics-server·Hubble | D18: metrics-server 설치, Cilium 에 Hubble Relay·UI 켜기 | E18: 박가람 | F18: 46305 | G18: 46305 | H18: =MAX(1,NETWORKDAYS(F18,G18,인덱스!$B$41:$B$47)) | I18: 완료 | J18: NFR-004-01 | K18: - | L18: k8s/metrics-server/, 10/10/14
A19: DEVOPS-018 | B19: 품질 | C19: 저장소 품질 검사 | D19: 비밀값 커밋 차단 pre-commit(mise + lefthook + gitleaks), shellcheck·`mise run lint`, tofu fmt·validate, yamllint·kubeconform(커밋될 내용 렌더), markdownlint, k8s/apply.sh·루트 kustomization | E19: 박가람 | F19: 46305 | G19: 46305 | H19: =MAX(1,NETWORKDAYS(F19,G19,인덱스!$B$41:$B$47)) | I19: 완료 | J19: NFR-003-01 | K19: - | L19: mise.toml, lefthook.yml, k8s/apply.sh, 10/10/15–23 | M19: W52–W57
A20: DEVOPS-019 | B20: 백업 | C20: 백업 체계 | D20: etcd 스냅샷 LaunchAgent 추가 → 손으로 실행하는 통합 backup.sh 로 변경, 비밀값 백업 재생성과 .backups/ 위치·권한, README 명령 모음, NAS 동기화 폴더 사본 | E20: 박가람 | F20: 46305 | G20: 46305 | H20: =MAX(1,NETWORKDAYS(F20,G20,인덱스!$B$41:$B$47)) | I20: 완료 | J20: NFR-003-04, NFR-004-01 | K20: - | L20: talos/backup.sh, docs/operations/secrets-backup.md, 10/10/13, 26–29, 32 | M20: W35, W36
A21: DEVOPS-020 | B21: 문서 | C21: 운영 문서·단일 출처 | D21: 재구축·Talos 업그레이드·접속 경로 runbook 3개, Talos 버전·노드 주소·API VIP 를 tofu/variables.tf 한 곳으로 | E21: 박가람 | F21: 46305 | G21: 46305 | H21: =MAX(1,NETWORKDAYS(F21,G21,인덱스!$B$41:$B$47)) | I21: 완료 | J21: NFR-007-02 | K21: - | L21: docs/operations/, tofu/variables.tf, 10/10/30, 31 | M21: W37, W41
A22: DEVOPS-021 | B22: 클러스터 | C22: 클러스터 재구축(새 비밀값) | D22: VM 6대 교체와 새 비밀값으로 전체 재구축 첫 실행, 재구축 뒤 첫 백업 확인, 옛 클러스터 묶음 3개 삭제 | E22: 박가람 | F22: 46305 | G22: 46305 | H22: =MAX(1,NETWORKDAYS(F22,G22,인덱스!$B$41:$B$47)) | I22: 완료 | J22: NFR-003-04 | K22: - | L22: 10/10/34, 36 | M22: W63. tofu replace/destroy 는 사용자가 실행
A23: DEVOPS-022 | B23: 장애시험 | C23: 전원 차단 시험 | D23: pve-2 정상 종료·전원 끔, 다시 켠 뒤 pve-3 정상 종료·전원 끔 — 클러스터 동작 관찰 | E23: 박가람 | F23: 46308 | G23: 46309 | H23: =MAX(1,NETWORKDAYS(F23,G23,인덱스!$B$41:$B$47)) | I23: 완료 | J23: NFR-004-01 | K23: - | L23: 10/13/01, 02 | M23: 기록 커밋 10/14
A24: DEVOPS-023 | B24: 네트워크 | C24: prd 네임스페이스·Cilium Ingress | D24: prd 네임스페이스(PSA restricted), Cilium Ingress 를 켜 LoadBalancer 하나(192.168.200.131)로 도메인별 라우팅 | E24: 박가람 | F24: 46311 | G24: 46311 | H24: =MAX(1,NETWORKDAYS(F24,G24,인덱스!$B$41:$B$47)) | I24: 완료 | J24: NFR-002-01, NFR-005-01 | K24: - | L24: k8s/namespaces/prd.yaml, k8s/cilium/values.yaml, 10/16/01 | M24: W65 일부
A25: DEVOPS-024 | B25: 배포 | C25: 프로토타입 dev 배포·앱 비밀값 규칙 | D25: Jeju-subsidence-AI 프로토타입을 dev 에 올리고 jeju-ai.dev.innopam.net 으로 열기, 앱 비밀값은 저장소 안 secrets/(gitignore)에 두고 백업에 포함 | E25: 박가람 | F25: 46314 | G25: 46314 | H25: =MAX(1,NETWORKDAYS(F25,G25,인덱스!$B$41:$B$47)) | I25: 완료 | J25: NFR-005-01, NFR-003-04 | K25: - | L25: 10/19/01–03 | M25: 10/20 에 jeju-ai-saas 로 교체
A26: DEVOPS-025 | B26: CI | C26: GitHub Actions 러너(ARC) | D26: dev·stage 쿼터를 각 1.5 CPU·2.5Gi 로 줄여 러너 몫 확보, W64 결정 7개, GitHub App 생성·설치·러너 그룹 dev0, ARC 설치(arc-systems·arc-runners, DinD, egress 제한), 실제 잡 시험(DinD 이미지 빌드) 통과 | E26: 박가람 | F26: 46314 | G26: 46314 | H26: =MAX(1,NETWORKDAYS(F26,G26,인덱스!$B$41:$B$47)) | I26: 완료 | J26: NFR-005-01 | K26: - | L26: k8s/arc/, 10/19/05–09 | M26: W64. runs-on: dev0
A27: DEVOPS-026 | B27: GitOps | C27: jeju-ai-saas dev 매니페스트·Argo CD 설치 | D27: jeju-ai-saas(FE·API·SeaweedFS) dev 매니페스트, Argo CD + Image Updater 설치(GitHub App 자격, argocd.dev.innopam.net, ImageUpdater CR·kustomization writeback) | E27: 박가람 | F27: 46314 | G27: 46314 | H27: =MAX(1,NETWORKDAYS(F27,G27,인덱스!$B$41:$B$47)) | I27: 완료 | J27: NFR-004-02, NFR-005-01 | K27: - | L27: apps/jeju-ai-saas/, k8s/argocd/, 10/19/10, 11 | M27: W67
A28: DEVOPS-027 | B28: GitOps | C28: develop 자동 배포 컷오버 | D28: jeju-ai-saas 를 Argo CD 로 dev 에 올리고 프로토타입 jeju-subsidence-ai 내림(W67 끝), 두 번째 develop push 가 사람 손 없이 반영되는 것 확인 | E28: 박가람 | F28: 46315 | G28: 46315 | H28: =MAX(1,NETWORKDAYS(F28,G28,인덱스!$B$41:$B$47)) | I28: 완료 | J28: NFR-004-02 | K28: - | L28: 10/20/01, ws 10/20/02
A29: DEVOPS-028 | B29: 보안 | C29: Argo CD 계정·백업 갱신 | D29: 초기 admin Secret 삭제·비밀번호 교체, 읽기 전용 임시 계정 temp, 비밀 파일 백업 갱신 | E29: 박가람 | F29: 46315 | G29: 46315 | H29: =MAX(1,NETWORKDAYS(F29,G29,인덱스!$B$41:$B$47)) | I29: 완료 | J29: NFR-003-04, NFR-003-05 | K29: - | L29: 10/20/02, 04
A30: DEVOPS-029 | B30: CI | C30: official-website build-push 워크플로 | D30: GitHub Actions(ubuntu-latest)에서 이미지 빌드·GHCR push, release 브랜치, 태그 규칙 | E30: 박가람 | F30: 46316 | G30: 46317 | H30: =MAX(1,NETWORKDAYS(F30,G30,인덱스!$B$41:$B$47)) | I30: 예정 | J30: NFR-005-01 | K30: - | L30: W66
A31: DEVOPS-030 | B31: 관측 | C31: 모니터링·알림 | D31: kube-prometheus-stack(보존 7일·PV 10 GB longhorn), NotReady·파드 재시작·디스크 포화 알림, Hubble UI 확인 | E31: 박가람 | F31: 46318 | G31: 46322 | H31: =MAX(1,NETWORKDAYS(F31,G31,인덱스!$B$41:$B$47)) | I31: 예정 | J31: NFR-004-01 | K31: - | L31: W48, W58
A32: DEVOPS-031 | B32: 백업 | C32: Longhorn 백업 대상·스토리지 예약 | D32: backup-target(NAS NFS)을 values 에 코드화, 워커 EPHEMERAL 파티션 예약 비율, 복원 시험 | E32: 박가람 | F32: 46323 | G32: 46324 | H32: =MAX(1,NETWORKDAYS(F32,G32,인덱스!$B$41:$B$47)) | I32: 예정 | J32: NFR-003-04, NFR-004-01 | K32: - | L32: W49, W50 | M32: 결정 필요
A33: DEVOPS-032 | B33: 장애시험 | C33: 장애 시험 2차 | D33: 컨트롤 플레인 2대 동시 불능(쿼럼 상실), Longhorn 복제본 워커 중단, 디스크 포화 — 복귀 시간·상태 기록 | E33: 박가람 | F33: 46325 | G33: 46328 | H33: =MAX(1,NETWORKDAYS(F33,G33,인덱스!$B$41:$B$47)) | I33: 예정 | J33: NFR-004-01 | K33: - | L33: W42
A34: DEVOPS-033 | B34: 보안 | C34: 인증서·접근 경로 정리 | D34: Proxmox 인증서 SAN 재발급·CA 신뢰, nginx 경유 VM 콘솔(WebSocket)·VIP 직접 접속 우회 확인, LimitRange max 결정 반영 | E34: 박가람 | F34: 46329 | G34: 46330 | H34: =MAX(1,NETWORKDAYS(F34,G34,인덱스!$B$41:$B$47)) | I34: 예정 | J34: NFR-003-01 | K34: - | L34: W43, W47, W59
A35: DEVOPS-034 | B35: DB | C35: PostgreSQL 운영 구성 | D35: CloudNativePG 3복제, Longhorn PV, 백업(WAL·스냅샷)·복원 시험, 시크릿 관리, dev 부터 적용 | E35: 박가람 | F35: 46331 | G35: 46336 | H35: =MAX(1,NETWORKDAYS(F35,G35,인덱스!$B$41:$B$47)) | I35: 예정 | J35: NFR-004-01, NFR-003-04 | K35: - | L35: apps/jeju-ai-saas/ | M35: BE 메타데이터 DB 전환 지원 (W16 방향)
A36: DEVOPS-035 | B36: 배포 | C36: 타일 제공 구성 | D36: PMTiles 를 S3 range 요청으로 직접 제공하거나 martin 타일 서버 배포, Ingress 캐시·압축, 용량·대역폭 확인 | E36: 박가람 | F36: 46337 | G36: 46339 | H36: =MAX(1,NETWORKDAYS(F36,G36,인덱스!$B$41:$B$47)) | I36: 예정 | J36: NFR-001-01 | K36: - | L36: apps/jeju-ai-saas/ | M36: BE 벡터 타일 전환과 함께
A37: DEVOPS-036 | B37: 배포 | C37: stage 환경·승격 절차 | D37: stage 네임스페이스에 jeju-ai-saas 배포, develop → stage 수동 승격(태그 고정), 롤백 절차 | E37: 박가람 | F37: 46342 | G37: 46344 | H37: =MAX(1,NETWORKDAYS(F37,G37,인덱스!$B$41:$B$47)) | I37: 예정 | J37: NFR-004-02 | K37: - | L37: apps/jeju-ai-saas/overlays/stage
